Discovered type 'process' for work pool 'steam_de'.
Worker 'ProcessWorker e1810d8a-0a63-4c73-8535-29f2cf88954c' started!

Failed the last 3 attempts. Please check your environment and configuration.
Examples of recent errors:

Traceback (most recent call last):
  File "/Users/davidgillespie/.local/share/virtualenvs/de-engineering-steam-jzXCFMkU/lib/python3.13/site-packages/httpx/_transports/default.py", line 101, in map_httpcore_exceptions
    yield
  File "/Users/davidgillespie/.local/share/virtualenvs/de-engineering-steam-jzXCFMkU/lib/python3.13/site-packages/httpx/_transports/default.py", line 394, in handle_async_request
    resp = await self._pool.handle_async_request(req)
           ^^^^^^^^^^^^^^^^^^^^^^^^^^^^^^^^^^^^^^^^^^
  File "/Users/davidgillespie/.local/share/virtualenvs/de-engineering-steam-jzXCFMkU/lib/python3.13/site-packages/httpcore/_async/connection_pool.py", line 256, in handle_async_request
    raise exc from None
  File "/Users/davidgillespie/.local/share/virtualenvs/de-engineering-steam-jzXCFMkU/lib/python3.13/site-packages/httpcore/_async/connection_pool.py", line 236, in handle_async_request
    response = await connection.handle_async_request(
               ^^^^^^^^^^^^^^^^^^^^^^^^^^^^^^^^^^^^^^
        pool_request.request
        ^^^^^^^^^^^^^^^^^^^^
    )
    ^
  File "/Users/davidgillespie/.local/share/virtualenvs/de-engineering-steam-jzXCFMkU/lib/python3.13/site-packages/httpcore/_async/connection.py", line 101, in handle_async_request
    raise exc
  File "/Users/davidgillespie/.local/share/virtualenvs/de-engineering-steam-jzXCFMkU/lib/python3.13/site-packages/httpcore/_async/connection.py", line 78, in handle_async_request
    stream = await self._connect(request)
             ^^^^^^^^^^^^^^^^^^^^^^^^^^^^
  File "/Users/davidgillespie/.local/share/virtualenvs/de-engineering-steam-jzXCFMkU/lib/python3.13/site-packages/httpcore/_async/connection.py", line 124, in _connect
    stream = await self._network_backend.connect_tcp(**kwargs)
             ^^^^^^^^^^^^^^^^^^^^^^^^^^^^^^^^^^^^^^^^^^^^^^^^^
  File "/Users/davidgillespie/.local/share/virtualenvs/de-engineering-steam-jzXCFMkU/lib/python3.13/site-packages/httpcore/_backends/auto.py", line 31, in connect_tcp
    return await self._backend.connect_tcp(
           ^^^^^^^^^^^^^^^^^^^^^^^^^^^^^^^^
    ...<5 lines>...
    )
    ^
  File "/Users/davidgillespie/.local/share/virtualenvs/de-engineering-steam-jzXCFMkU/lib/python3.13/site-packages/httpcore/_backends/anyio.py", line 113, in connect_tcp
    with map_exceptions(exc_map):
         ~~~~~~~~~~~~~~^^^^^^^^^
  File "/opt/homebrew/Cellar/python@3.13/3.13.2/Frameworks/Python.framework/Versions/3.13/lib/python3.13/contextlib.py", line 162, in __exit__
    self.gen.throw(value)
    ~~~~~~~~~~~~~~^^^^^^^
  File "/Users/davidgillespie/.local/share/virtualenvs/de-engineering-steam-jzXCFMkU/lib/python3.13/site-packages/httpcore/_exceptions.py", line 14, in map_exceptions
    raise to_exc(exc) from exc
httpcore.ConnectError: All connection attempts failed

The above exception was the direct cause of the following exception:

Traceback (most recent call last):
  File "/Users/davidgillespie/.local/share/virtualenvs/de-engineering-steam-jzXCFMkU/lib/python3.13/site-packages/prefect/utilities/services.py", line 64, in critical_service_loop
    await workload()
  File "/Users/davidgillespie/.local/share/virtualenvs/de-engineering-steam-jzXCFMkU/lib/python3.13/site-packages/prefect/workers/base.py", line 762, in get_and_submit_flow_runs
    runs_response = await self._get_scheduled_flow_runs()
                    ^^^^^^^^^^^^^^^^^^^^^^^^^^^^^^^^^^^^^
  File "/Users/davidgillespie/.local/share/virtualenvs/de-engineering-steam-jzXCFMkU/lib/python3.13/site-packages/prefect/workers/base.py", line 921, in _get_scheduled_flow_runs
    await self.client.get_scheduled_flow_runs_for_work_pool(
    ...<3 lines>...
    )
  File "/Users/davidgillespie/.local/share/virtualenvs/de-engineering-steam-jzXCFMkU/lib/python3.13/site-packages/prefect/client/orchestration/_work_pools/client.py", line 586, in get_scheduled_flow_runs_for_work_pool
    response = await self.request(
               ^^^^^^^^^^^^^^^^^^^
    ...<4 lines>...
    )
    ^
  File "/Users/davidgillespie/.local/share/virtualenvs/de-engineering-steam-jzXCFMkU/lib/python3.13/site-packages/prefect/client/orchestration/base.py", line 53, in request
    return await self._client.send(request)
           ^^^^^^^^^^^^^^^^^^^^^^^^^^^^^^^^
  File "/Users/davidgillespie/.local/share/virtualenvs/de-engineering-steam-jzXCFMkU/lib/python3.13/site-packages/prefect/client/base.py", line 330, in send
    response = await self._send_with_retry(
               ^^^^^^^^^^^^^^^^^^^^^^^^^^^^
    ...<24 lines>...
    )
    ^
  File "/Users/davidgillespie/.local/share/virtualenvs/de-engineering-steam-jzXCFMkU/lib/python3.13/site-packages/prefect/client/base.py", line 250, in _send_with_retry
    response = await send(request, *send_args, **send_kwargs)
               ^^^^^^^^^^^^^^^^^^^^^^^^^^^^^^^^^^^^^^^^^^^^^^
  File "/Users/davidgillespie/.local/share/virtualenvs/de-engineering-steam-jzXCFMkU/lib/python3.13/site-packages/httpx/_client.py", line 1629, in send
    response = await self._send_handling_auth(
               ^^^^^^^^^^^^^^^^^^^^^^^^^^^^^^^
    ...<4 lines>...
    )
    ^
  File "/Users/davidgillespie/.local/share/virtualenvs/de-engineering-steam-jzXCFMkU/lib/python3.13/site-packages/httpx/_client.py", line 1657, in _send_handling_auth
    response = await self._send_handling_redirects(
               ^^^^^^^^^^^^^^^^^^^^^^^^^^^^^^^^^^^^
    ...<3 lines>...
    )
    ^
  File "/Users/davidgillespie/.local/share/virtualenvs/de-engineering-steam-jzXCFMkU/lib/python3.13/site-packages/httpx/_client.py", line 1694, in _send_handling_redirects
    response = await self._send_single_request(request)
               ^^^^^^^^^^^^^^^^^^^^^^^^^^^^^^^^^^^^^^^^
  File "/Users/davidgillespie/.local/share/virtualenvs/de-engineering-steam-jzXCFMkU/lib/python3.13/site-packages/httpx/_client.py", line 1730, in _send_single_request
    response = await transport.handle_async_request(request)
               ^^^^^^^^^^^^^^^^^^^^^^^^^^^^^^^^^^^^^^^^^^^^^
  File "/Users/davidgillespie/.local/share/virtualenvs/de-engineering-steam-jzXCFMkU/lib/python3.13/site-packages/httpx/_transports/default.py", line 393, in handle_async_request
    with map_httpcore_exceptions():
         ~~~~~~~~~~~~~~~~~~~~~~~^^
  File "/opt/homebrew/Cellar/python@3.13/3.13.2/Frameworks/Python.framework/Versions/3.13/lib/python3.13/contextlib.py", line 162, in __exit__
    self.gen.throw(value)
    ~~~~~~~~~~~~~~^^^^^^^
  File "/Users/davidgillespie/.local/share/virtualenvs/de-engineering-steam-jzXCFMkU/lib/python3.13/site-packages/httpx/_transports/default.py", line 118, in map_httpcore_exceptions
    raise mapped_exc(message) from exc
httpx.ConnectError: All connection attempts failed


Backing off due to consecutive errors, using increased interval of  20.0s.

Failed the last 3 attempts. Please check your environment and configuration.
Examples of recent errors:

Traceback (most recent call last):
  File "/Users/davidgillespie/.local/share/virtualenvs/de-engineering-steam-jzXCFMkU/lib/python3.13/site-packages/httpx/_transports/default.py", line 101, in map_httpcore_exceptions
    yield
  File "/Users/davidgillespie/.local/share/virtualenvs/de-engineering-steam-jzXCFMkU/lib/python3.13/site-packages/httpx/_transports/default.py", line 394, in handle_async_request
    resp = await self._pool.handle_async_request(req)
           ^^^^^^^^^^^^^^^^^^^^^^^^^^^^^^^^^^^^^^^^^^
  File "/Users/davidgillespie/.local/share/virtualenvs/de-engineering-steam-jzXCFMkU/lib/python3.13/site-packages/httpcore/_async/connection_pool.py", line 256, in handle_async_request
    raise exc from None
  File "/Users/davidgillespie/.local/share/virtualenvs/de-engineering-steam-jzXCFMkU/lib/python3.13/site-packages/httpcore/_async/connection_pool.py", line 236, in handle_async_request
    response = await connection.handle_async_request(
               ^^^^^^^^^^^^^^^^^^^^^^^^^^^^^^^^^^^^^^
        pool_request.request
        ^^^^^^^^^^^^^^^^^^^^
    )
    ^
  File "/Users/davidgillespie/.local/share/virtualenvs/de-engineering-steam-jzXCFMkU/lib/python3.13/site-packages/httpcore/_async/connection.py", line 101, in handle_async_request
    raise exc
  File "/Users/davidgillespie/.local/share/virtualenvs/de-engineering-steam-jzXCFMkU/lib/python3.13/site-packages/httpcore/_async/connection.py", line 78, in handle_async_request
    stream = await self._connect(request)
             ^^^^^^^^^^^^^^^^^^^^^^^^^^^^
  File "/Users/davidgillespie/.local/share/virtualenvs/de-engineering-steam-jzXCFMkU/lib/python3.13/site-packages/httpcore/_async/connection.py", line 124, in _connect
    stream = await self._network_backend.connect_tcp(**kwargs)
             ^^^^^^^^^^^^^^^^^^^^^^^^^^^^^^^^^^^^^^^^^^^^^^^^^
  File "/Users/davidgillespie/.local/share/virtualenvs/de-engineering-steam-jzXCFMkU/lib/python3.13/site-packages/httpcore/_backends/auto.py", line 31, in connect_tcp
    return await self._backend.connect_tcp(
           ^^^^^^^^^^^^^^^^^^^^^^^^^^^^^^^^
    ...<5 lines>...
    )
    ^
  File "/Users/davidgillespie/.local/share/virtualenvs/de-engineering-steam-jzXCFMkU/lib/python3.13/site-packages/httpcore/_backends/anyio.py", line 113, in connect_tcp
    with map_exceptions(exc_map):
         ~~~~~~~~~~~~~~^^^^^^^^^
  File "/opt/homebrew/Cellar/python@3.13/3.13.2/Frameworks/Python.framework/Versions/3.13/lib/python3.13/contextlib.py", line 162, in __exit__
    self.gen.throw(value)
    ~~~~~~~~~~~~~~^^^^^^^
  File "/Users/davidgillespie/.local/share/virtualenvs/de-engineering-steam-jzXCFMkU/lib/python3.13/site-packages/httpcore/_exceptions.py", line 14, in map_exceptions
    raise to_exc(exc) from exc
httpcore.ConnectError: All connection attempts failed

The above exception was the direct cause of the following exception:

Traceback (most recent call last):
  File "/Users/davidgillespie/.local/share/virtualenvs/de-engineering-steam-jzXCFMkU/lib/python3.13/site-packages/prefect/utilities/services.py", line 64, in critical_service_loop
    await workload()
  File "/Users/davidgillespie/.local/share/virtualenvs/de-engineering-steam-jzXCFMkU/lib/python3.13/site-packages/prefect/workers/base.py", line 762, in get_and_submit_flow_runs
    runs_response = await self._get_scheduled_flow_runs()
                    ^^^^^^^^^^^^^^^^^^^^^^^^^^^^^^^^^^^^^
  File "/Users/davidgillespie/.local/share/virtualenvs/de-engineering-steam-jzXCFMkU/lib/python3.13/site-packages/prefect/workers/base.py", line 921, in _get_scheduled_flow_runs
    await self.client.get_scheduled_flow_runs_for_work_pool(
    ...<3 lines>...
    )
  File "/Users/davidgillespie/.local/share/virtualenvs/de-engineering-steam-jzXCFMkU/lib/python3.13/site-packages/prefect/client/orchestration/_work_pools/client.py", line 586, in get_scheduled_flow_runs_for_work_pool
    response = await self.request(
               ^^^^^^^^^^^^^^^^^^^
    ...<4 lines>...
    )
    ^
  File "/Users/davidgillespie/.local/share/virtualenvs/de-engineering-steam-jzXCFMkU/lib/python3.13/site-packages/prefect/client/orchestration/base.py", line 53, in request
    return await self._client.send(request)
           ^^^^^^^^^^^^^^^^^^^^^^^^^^^^^^^^
  File "/Users/davidgillespie/.local/share/virtualenvs/de-engineering-steam-jzXCFMkU/lib/python3.13/site-packages/prefect/client/base.py", line 330, in send
    response = await self._send_with_retry(
               ^^^^^^^^^^^^^^^^^^^^^^^^^^^^
    ...<24 lines>...
    )
    ^
  File "/Users/davidgillespie/.local/share/virtualenvs/de-engineering-steam-jzXCFMkU/lib/python3.13/site-packages/prefect/client/base.py", line 250, in _send_with_retry
    response = await send(request, *send_args, **send_kwargs)
               ^^^^^^^^^^^^^^^^^^^^^^^^^^^^^^^^^^^^^^^^^^^^^^
  File "/Users/davidgillespie/.local/share/virtualenvs/de-engineering-steam-jzXCFMkU/lib/python3.13/site-packages/httpx/_client.py", line 1629, in send
    response = await self._send_handling_auth(
               ^^^^^^^^^^^^^^^^^^^^^^^^^^^^^^^
    ...<4 lines>...
    )
    ^
  File "/Users/davidgillespie/.local/share/virtualenvs/de-engineering-steam-jzXCFMkU/lib/python3.13/site-packages/httpx/_client.py", line 1657, in _send_handling_auth
    response = await self._send_handling_redirects(
               ^^^^^^^^^^^^^^^^^^^^^^^^^^^^^^^^^^^^
    ...<3 lines>...
    )
    ^
  File "/Users/davidgillespie/.local/share/virtualenvs/de-engineering-steam-jzXCFMkU/lib/python3.13/site-packages/httpx/_client.py", line 1694, in _send_handling_redirects
    response = await self._send_single_request(request)
               ^^^^^^^^^^^^^^^^^^^^^^^^^^^^^^^^^^^^^^^^
  File "/Users/davidgillespie/.local/share/virtualenvs/de-engineering-steam-jzXCFMkU/lib/python3.13/site-packages/httpx/_client.py", line 1730, in _send_single_request
    response = await transport.handle_async_request(request)
               ^^^^^^^^^^^^^^^^^^^^^^^^^^^^^^^^^^^^^^^^^^^^^
  File "/Users/davidgillespie/.local/share/virtualenvs/de-engineering-steam-jzXCFMkU/lib/python3.13/site-packages/httpx/_transports/default.py", line 393, in handle_async_request
    with map_httpcore_exceptions():
         ~~~~~~~~~~~~~~~~~~~~~~~^^
  File "/opt/homebrew/Cellar/python@3.13/3.13.2/Frameworks/Python.framework/Versions/3.13/lib/python3.13/contextlib.py", line 162, in __exit__
    self.gen.throw(value)
    ~~~~~~~~~~~~~~^^^^^^^
  File "/Users/davidgillespie/.local/share/virtualenvs/de-engineering-steam-jzXCFMkU/lib/python3.13/site-packages/httpx/_transports/default.py", line 118, in map_httpcore_exceptions
    raise mapped_exc(message) from exc
httpx.ConnectError: All connection attempts failed
